Workbook

Sheet 1. Table of Contents
A1: 📚 MICROSOFT EXCEL TRAINING MATERIAL: INTERMEDIATE TO ADVANCED
A2: Complete Training Guide with Practical Case Study
A4: 📋 TABLE OF CONTENTS
A6: Sheet # | B6: Topic | C6: Level | D6: Description
A7: 1 | B7: Table of Contents | C7: — | D7: Overview of training materials
A8: 2 | B8: Intermediate Formulas | C8: Intermediate | D8: SUMIFS, COUNTIFS, INDEX-MATCH, TEXT functions
A9: 3 | B9: Advanced Formulas | C9: Advanced | D9: XLOOKUP, Dynamic Arrays, LET, LAMBDA
A10: 4 | B10: Data Analysis Tools | C10: Intermediate | D10: Pivot Tables, Data Validation, Conditional Formatting
A11: 5 | B11: Advanced Features | C11: Advanced | D11: Power Query basics, Named Ranges, Data Models
A12: 6 | B12: Case Study - Data | C12: Practical | D12: Sales dataset for hands-on practice
A13: 7 | B13: Case Study - Analysis | C13: Practical | D13: Step-by-step analysis walkthrough
A14: 8 | B14: Practice Exercises | C14: All Levels | D14: Exercises to reinforce learning
A16: 💡 Learning Objectives:
A17: • Master intermediate and advanced Excel formulas
A18: • Build complex data analysis solutions
A19: • Apply skills to real-world business scenarios
A20: • Develop problem-solving approaches using Excel
A21: • Create dynamic reports and dashboards
A23: ⌨️ Essential Keyboard Shortcuts:
A24: Shortcut | B24: Action
A25: Ctrl + C/V/X | B25: Copy/Paste/Cut
A26: Ctrl + Z/Y | B26: Undo/Redo
A27: Ctrl + S | B27: Save
A28: Ctrl + T | B28: Create Table
A29: Ctrl + Shift + L | B29: Toggle Filters
A30: F2 | B30: Edit Cell
A31: F4 | B31: Toggle Absolute Reference ($)
A32: Alt + Enter | B32: New Line in Cell
A33: Ctrl + ; | B33: Insert Today's Date
A34: Ctrl + Shift + ; | B34: Insert Current Time
A35: Ctrl + ` | B35: Show/Hide Formulas
... A37: Ctrl + End | B37: Go to Last Used Cell

Sheet 2. Intermediate Formulas
A1: 📊 INTERMEDIATE EXCEL FORMULAS
A3: 🔹 SECTION 1: CONDITIONAL AGGREGATION FUNCTIONS
A5: Function | B5: Syntax | C5: Description
A6: SUMIF | B6: SUMIF(range, criteria, sum_range) | C6: Sum cells meeting ONE condition
A7: SUMIFS | B7: SUMIFS(sum_range, range1, criteria1, ...) | C7: Sum cells meeting MULTIPLE conditions
A8: COUNTIF | B8: COUNTIF(range, criteria) | C8: Count cells meeting ONE condition
A9: COUNTIFS | B9: COUNTIFS(range1, criteria1, range2, criteria2) | C9: Count cells meeting MULTIPLE conditions
A10: AVERAGEIF | B10: AVERAGEIF(range, criteria, average_range) | C10: Average cells meeting ONE condition
A11: AVERAGEIFS | B11: AVERAGEIFS(avg_range, range1, criteria1, ...) | C11: Average cells meeting MULTIPLE conditions
A13: 📋 Practice Data: | F13: 📝 Formula Examples (with live results):
A14: Product | B14: Region | C14: Sales | D14: Quantity | F14: Description | G14: Formula | H14: Result
A15: Apple | B15: North | C15: 150 | D15: 60 | F15: Sum all Apple sales | G15: SUMIF(A15:A21,"Apple",C15:C21) | H15: =SUMIF(A15:A21,"Apple",C15:C21) -> 420
A16: Orange | B16: South | C16: 200 | D16: 45 | F16: Sum Apple sales in North | G16: SUMIFS(C15:C21,A15:A21,"Apple",B15:B21,"North") | H16: =SUMIFS(C15:C21,A15:A21,"Apple",B15:B21,"North") -> 240
A17: Apple | B17: South | C17: 180 | D17: 70 | F17: Count Apple products | G17: COUNTIF(A15:A21,"Apple") | H17: =COUNTIF(A15:A21,"Apple") -> 3
A18: Banana | B18: North | C18: 120 | D18: 30 | F18: Count Apple in North | G18: COUNTIFS(A15:A21,"Apple",B15:B21,"North") | H18: =COUNTIFS(A15:A21,"Apple",B15:B21,"North") -> 2
A19: Apple | B19: North | C19: 90 | D19: 55 | F19: Average Apple sales | G19: AVERAGEIF(A15:A21,"Apple",C15:C21) | H19: =AVERAGEIF(A15:A21,"Apple",C15:C21) -> 140
A20: Orange | B20: North | C20: 160 | D20: 40 | F20: Sum sales where Qty>50 | G20: SUMIFS(C15:C21,D15:D21,">50") | H20: =SUMIFS(C15:C21,D15:D21,">50") -> 420
A21: Banana | B21: South | C21: 140 | D21: 35
A23: 🔹 SECTION 2: INDEX-MATCH (Powerful Lookup Alternative)
A25: Why INDEX-MATCH over VLOOKUP?
A26: • Can look up values to the LEFT (VLOOKUP cannot)
A27: • More flexible and efficient for large datasets
A28: • Does not break when columns are inserted/deleted
A29: • Can perform two-way lookups (row and column)
A31: Syntax: INDEX(return_range, MATCH(lookup_value, lookup_range, 0))
A33: Employee ID | B33: Name | C33: Department | D33: Salary | F33: Lookup Examples:
A34: E001 | B34: John Smith | C34: Sales | D34: 55000 | F34: Find Name for E003: | H34: =INDEX(B34:B38,MATCH("E003",A34:A38,0)) -> Bob Wilson
A35: E002 | B35: Jane Doe | C35: Marketing | D35: 62000 | F35: Find Salary for Jane Doe: | H35: =INDEX(D34:D38,MATCH("Jane Doe",B34:B38,0)) -> 62000
A36: E003 | B36: Bob Wilson | C36: IT | D36: 75000 | F36: Find Dept for E004: | H36: =INDEX(C34:C38,MATCH("E004",A34:A38,0)) -> HR
A37: E004 | B37: Alice Brown | C37: HR | D37: 58000 | F37: Find ID for IT dept: | H37: =INDEX(A34:A38,MATCH("IT",C34:C38,0)) -> E003
A38: E005 | B38: Mike Johnson | C38: Finance | D38: 68000
A40: 🔹 SECTION 3: TEXT FUNCTIONS
A42: Function | B42: Description | C42: Example Input | D42: Result
A43: LEFT(text, num_chars) | B43: Extract characters from left | C43: John Smith | D43: =LEFT("John Smith",4) -> John
A44: RIGHT(text, num_chars) | B44: Extract characters from right | C44: John Smith | D44: =RIGHT("John Smith",5) -> Smith
A45: MID(text, start, num_chars) | B45: Extract from middle | C45: John Smith | D45: =MID("John Smith",6,5) -> Smith
A46: LEN(text) | B46: Count characters | C46: Excel Training | D46: =LEN("Excel Training") -> 14
A47: TRIM(text) | B47: Remove extra spaces | C47: Hello World | D47: =TRIM(" Hello World ") -> Hello World
A48: UPPER(text) | B48: Convert to uppercase | C48: excel | D48: =UPPER("excel") -> EXCEL
A49: LOWER(text) | B49: Convert to lowercase | C49: EXCEL | D49: =LOWER("EXCEL") -> excel
...

Sheet 3. Advanced Formulas
A1: 🚀 ADVANCED EXCEL FORMULAS
A3: 🔹 SECTION 1: XLOOKUP (Modern Lookup Function)
A5: Syntax: XLOOKUP(lookup_value, lookup_array, return_array, [if_not_found], [match_mode], [search_mode])
A7: Advantages over VLOOKUP:
A8: • Default exact match (no need for FALSE/0)
A9: • Can look left or right
A10: • Can return multiple columns
A11: • Built-in error handling with if_not_found
A12: • Supports wildcards and approximate matching
A14: Product ID | B14: Product Name | C14: Category | D14: Price | E14: Stock | G14: XLOOKUP Examples:
A15: P001 | B15: Laptop | C15: Electronics | D15: 999.99 | E15: 45 | G15: Find name for P003: | I15: =_xlfn.XLOOKUP("P003",A15:A19,B15:B19) -> Desk Chair
A16: P002 | B16: Mouse | C16: Electronics | D16: 29.99 | E16: 150 | G16: Find price of Mouse: | I16: =_xlfn.XLOOKUP("Mouse",B15:B19,D15:D19) -> 29.99
A17: P003 | B17: Desk Chair | C17: Furniture | D17: 249.99 | E17: 30 | G17: With error handling: | I17: =_xlfn.XLOOKUP("P999",A15:A19,B15:B19,"Not Found") -> Not Found
A18: P004 | B18: Monitor | C18: Electronics | D18: 349.99 | E18: 60 | G18: Return multiple cols: | I18: {=_xlfn.XLOOKUP("P002",A15:A19,B15:E19)} -> Mouse | J18: Electronics | K18: 29.99 | L18: 150
A19: P005 | B19: Keyboard | C19: Electronics | D19: 79.99 | E19: 100
A21: 🔹 SECTION 2: DYNAMIC ARRAY FUNCTIONS
A23: Dynamic arrays automatically spill results into adjacent cells
A24: Use the # symbol to reference the entire spill range
A26: Function | B26: Description | C26: Example
A27: FILTER | B27: Filter data based on criteria | C27: FILTER(range, criteria)
A28: SORT | B28: Sort data by specified column | C28: SORT(range, sort_index, order)
A29: SORTBY | B29: Sort by separate column/range | C29: SORTBY(range, by_array, order)
A30: UNIQUE | B30: Return unique values | C30: UNIQUE(range)
A31: SEQUENCE | B31: Generate sequence of numbers | C31: SEQUENCE(rows, cols, start, step)
A32: RANDARRAY | B32: Generate random numbers | C32: RANDARRAY(rows, cols, min, max)
A34: Name | B34: Department | C34: Salary | D34: Years | F34: Dynamic Array Examples:
A35: Anna | B35: Sales | C35: 52000 | D35: 3 | F35: UNIQUE departments: | H35: {=_xlfn.UNIQUE(B35:B40)} -> Sales
A36: Brian | B36: IT | C36: 68000 | D36: 5 | H36: IT
A37: Carol | B37: Sales | C37: 55000 | D37: 4 | H37: HR
A38: David | B38: HR | C38: 48000 | D38: 2 | F38: Filter IT staff: | H38: {=_xlfn._xlws.FILTER(A35:D40,B35:B40="IT")} -> Brian | I38: IT | J38: 68000 | K38: 5
A39: Emma | B39: IT | C39: 72000 | D39: 6 | H39: Emma | I39: IT | J39: 72000 | K39: 6
A40: Frank | B40: Sales | C40: 58000 | D40: 5
F41: Sort by Salary (desc): | H41: {=_xlfn._xlws.SORT(A35:D40,3,-1)} -> Emma | I41: IT | J41: 72000 | K41: 6
H42: Brian | I42: IT | J42: 68000 | K42: 5
H43: Frank | I43: Sales | J43: 58000 | K43: 5
H44: Carol | I44: Sales | J44: 55000 | K44: 4
H45: Anna | I45: Sales | J45: 52000 | K45: 3
H46: David | I46: HR | J46: 48000 | K46: 2
F47: Sequence 1-5: | H47: {=_xlfn.SEQUENCE(5,1,1,1)} -> 1
H48: 2
...

Sheet 4. Data Analysis Tools
A1: 📈 DATA ANALYSIS TOOLS
A3: 🔹 SECTION 1: PIVOT TABLES
A5: Pivot Tables - Summarize and analyze large datasets
A7: Key Concepts:
A8: • Rows: Categories to group data vertically
A9: • Columns: Categories to group data horizontally
A10: • Values: Data to summarize (SUM, COUNT, AVG, etc.)
A11: • Filters: Criteria to filter the entire pivot table
A13: Steps to Create a Pivot Table:
A14: 1. Select your data range (including headers)
A15: 2. Insert > PivotTable
A16: 3. Choose where to place the pivot table
... A31: Validation Types:
A32: Type | B32: Description | C32: Use Case
A33: List | B33: Dropdown list of values | C33: Select from predefined options
A34: Whole Number | B34: Integer within range | C34: Age, quantity, count
A35: Decimal | B35: Decimal within range | C35: Price, percentage
A36: Date | B36: Date within range | C36: Start/end dates
A37: Time | B37: Time within range | C37: Working hours
A38: Text Length | B38: Limit character count | C38: Codes, abbreviations
A39: Custom | B39: Formula-based validation | C39: Complex business rules
A41: 🔹 SECTION 3: CONDITIONAL FORMATTING
A43: Conditional Formatting - Automatically format cells based on values | D43: Example - Color Scale:
D44: Score
A45: Access: Home tab > Conditional Formatting | D45: 95
D46: 78
A47: Common Formatting Rules: | D47: 62
A48: Rule Type | B48: Description | D48: 88
A49: Highlight Cell Rules | B49: Format cells >, <, =, between, containing text | D49: 45
A50: Top/Bottom Rules | B50: Format top/bottom N values or percentages | D50: 91
A51: Data Bars | B51: Show bars proportional to cell values
A52: Color Scales | B52: Gradient colors based on value range
A53: Icon Sets | B53: Symbols indicating value categories
A54: Custom Formula | B54: Format based on any formula returning TRUE

Sheet 5. Advanced Features
A1: ⚡ ADVANCED EXCEL FEATURES
A3: 🔹 SECTION 1: NAMED RANGES
A5: Named Ranges - Give meaningful names to cell references
A7: Benefits:
A8: • Make formulas more readable: =SUM(Sales) vs =SUM(B2:B100)
A9: • Easier to maintain - update range in one place
A10: • Auto-expand with dynamic named ranges
A12: How to Create:
A13: Method 1: Select cells > Name Box (left of formula bar) > Type name
A14: Method 2: Formulas tab > Define Name
A15: Method 3: Create from Selection (use headers as names)
A17: Naming Rules:
... A54: Common Transformations:
A55: Transformation | B55: Description
A56: Remove Columns | B56: Delete unwanted columns
A57: Filter Rows | B57: Keep/remove rows based on criteria
A58: Change Type | B58: Convert data types
A59: Replace Values | B59: Find and replace in columns
A60: Split Column | B60: Divide by delimiter or characters
A61: Merge Columns | B61: Combine multiple columns
A62: Pivot/Unpivot | B62: Reshape data structure
A63: Group By | B63: Aggregate data by categories

Sheet 6. Case Study - Data
A1: 📊 CASE STUDY: REGIONAL SALES ANALYSIS
A3: 📋 SCENARIO
A5: You are a data analyst at TechMart, a retail company selling electronics and office supplies.
A6: Your manager has asked you to analyze Q1 2024 sales data to identify trends and insights.
A7: Use the dataset below to complete the analysis tasks on the next sheet.
A9: 📦 SALES DATASET (Q1 2024) | J9: 📊 Summary Reference
A10: Order_ID | B10: Date | C10: Region | D10: Category | E10: Product | F10: Quantity | G10: Unit_Price | H10: Total_Sales | J10: Metric | K10: Value
A11: ORD001 | B11: 45296 | C11: North | D11: Electronics | E11: Laptop | F11: 2 | G11: 899.99 | H11: =F11*G11 -> 1799.98 | J11: Total Orders | K11: =COUNTA(A11:A40) -> 30
A12: ORD002 | B12: 45299 | C12: South | D12: Office | E12: Desk Chair | F12: 5 | G12: 149.99 | H12: =F12*G12 -> 749.95 | J12: Total Revenue | K12: =SUM(H11:H40) -> 32877.95
A13: ORD003 | B13: 45303 | C13: East | D13: Electronics | E13: Monitor | F13: 3 | G13: 299.99 | H13: =F13*G13 -> 899.97 | J13: Avg Order Value | K13: =AVERAGE(H11:H40) -> 1095.9317
A14: ORD004 | B14: 45306 | C14: West | D14: Office | E14: Printer | F14: 2 | G14: 199.99 | H14: =F14*G14 -> 399.98 | J14: Total Quantity | K14: =SUM(F11:F40) -> 205
A15: ORD005 | B15: 45309 | C15: North | D15: Electronics | E15: Keyboard | F15: 10 | G15: 59.99 | H15: =F15*G15 -> 599.9 | J15: Unique Products | K15: =COUNTA(_xlfn.UNIQUE(E11:E40)) -> 10
A16: ORD006 | B16: 45313 | C16: South | D16: Electronics | E16: Mouse | F16: 15 | G16: 29.99 | H16: =F16*G16 -> 449.85 | J16: Regions | K16: =COUNTA(_xlfn.UNIQUE(C11:C40)) -> 4
A17: ORD007 | B17: 45316 | C17: East | D17: Office | E17: Desk | F17: 2 | G17: 349.99 | H17: =F17*G17 -> 699.98
A18: ORD008 | B18: 45319 | C18: West | D18: Electronics | E18: Headphones | F18: 8 | G18: 79.99 | H18: =F18*G18 -> 639.92
A19: ORD009 | B19: 45324 | C19: North | D19: Office | E19: Filing Cabinet | F19: 3 | G19: 129.99 | H19: =F19*G19 -> 389.97
A20: ORD010 | B20: 45327 | C20: South | D20: Electronics | E20: Laptop | F20: 4 | G20: 899.99 | H20: =F20*G20 -> 3599.96
A21: ORD011 | B21: 45330 | C21: East | D21: Office | E21: Desk Chair | F21: 6 | G21: 149.99 | H21: =F21*G21 -> 899.94
A22: ORD012 | B22: 45334 | C22: West | D22: Electronics | E22: Monitor | F22: 5 | G22: 299.99 | H22: =F22*G22 -> 1499.95
A23: ORD013 | B23: 45337 | C23: North | D23: Electronics | E23: Tablet | F23: 3 | G23: 499.99 | H23: =F23*G23 -> 1499.97
A24: ORD014 | B24: 45340 | C24: South | D24: Office | E24: Desk | F24: 4 | G24: 349.99 | H24: =F24*G24 -> 1399.96
A25: ORD015 | B25: 45344 | C25: East | D25: Electronics | E25: Laptop | F25: 2 | G25: 899.99 | H25: =F25*G25 -> 1799.98
A26: ORD016 | B26: 45347 | C26: West | D26: Office | E26: Printer | F26: 3 | G26: 199.99 | H26: =F26*G26 -> 599.97
A27: ORD017 | B27: 45350 | C27: North | D27: Electronics | E27: Mouse | F27: 20 | G27: 29.99 | H27: =F27*G27 -> 599.8
A28: ORD018 | B28: 45353 | C28: South | D28: Electronics | E28: Keyboard | F28: 12 | G28: 59.99 | H28: =F28*G28 -> 719.88
... A40: ORD030 | B40: 45382 | C40: South | D40: Electronics | E40: Headphones | F40: 12 | G40: 79.99 | H40: =F40*G40 -> 959.88

Sheet 7. Case Study - Analysis
A1: 📊 CASE STUDY: ANALYSIS WALKTHROUGH
A3: 📝 TASK 1: Analyze Sales by Region
A4: Use SUMIFS to calculate total sales per region
A6: Region | B6: Total Sales | C6: Order Count | D6: Avg Order Value
A7: North | B7: =SUMIFS('6. Case Study - Data'!H11:H40,'6. Case Study - Data'!C11:C40,A7) -> 7789.5 | C7: =COUNTIF('6. Case Study - Data'!C11:C40,A7) -> 8 | D7: =B7/C7 -> 973.6875
A8: South | B8: =SUMIFS('6. Case Study - Data'!H11:H40,'6. Case Study - Data'!C11:C40,A8) -> 10779.41 | C8: =COUNTIF('6. Case Study - Data'!C11:C40,A8) -> 8 | D8: =B8/C8 -> 1347.4262
A9: East | B9: =SUMIFS('6. Case Study - Data'!H11:H40,'6. Case Study - Data'!C11:C40,A9) -> 8419.65 | C9: =COUNTIF('6. Case Study - Data'!C11:C40,A9) -> 7 | D9: =B9/C9 -> 1202.8071
A10: West | B10: =SUMIFS('6. Case Study - Data'!H11:H40,'6. Case Study - Data'!C11:C40,A10) -> 5889.39 | C10: =COUNTIF('6. Case Study - Data'!C11:C40,A10) -> 7 | D10: =B10/C10 -> 841.34143
A11: TOTAL | B11: =SUM(B7:B10) -> 32877.95 | C11: =SUM(C7:C10) -> 30 | D11: =B11/C11 -> 1095.9317
A13: 📝 TASK 2: Analyze Sales by Category
A14: Compare Electronics vs Office supplies performance
A16: Category | B16: Total Sales | C16: % of Total | D16: Qty Sold
A17: Electronics | B17: =SUMIFS('6. Case Study - Data'!H11:H40,'6. Case Study - Data'!D11:D40,A17) -> 23918.42 | C17: =B17/SUM(B17:B18) -> 0.72749122 | D17: =SUMIFS('6. Case Study - Data'!F11:F40,'6. Case Study - Data'!D11:D40,A17) -> 158
A18: Office | B18: =SUMIFS('6. Case Study - Data'!H11:H40,'6. Case Study - Data'!D11:D40,A18) -> 8959.53 | C18: =B18/SUM(B17:B18) -> 0.27250878 | D18: =SUMIFS('6. Case Study - Data'!F11:F40,'6. Case Study - Data'!D11:D40,A18) -> 47
A20: 📝 TASK 3: Identify Top-Selling Products
A21: Find total sales for each product using SUMIF
A23: Product | B23: Total Sales | C23: Quantity Sold
A24: Laptop | B24: =SUMIFS('6. Case Study - Data'!H11:H40,'6. Case Study - Data'!E11:E40,A24) -> 9899.89 | C24: =SUMIFS('6. Case Study - Data'!F11:F40,'6. Case Study - Data'!E11:E40,A24) -> 11
A25: Monitor | B25: =SUMIFS('6. Case Study - Data'!H11:H40,'6. Case Study - Data'!E11:E40,A25) -> 3599.88 | C25: =SUMIFS('6. Case Study - Data'!F11:F40,'6. Case Study - Data'!E11:E40,A25) -> 12
A26: Tablet | B26: =SUMIFS('6. Case Study - Data'!H11:H40,'6. Case Study - Data'!E11:E40,A26) -> 3999.92 | C26: =SUMIFS('6. Case Study - Data'!F11:F40,'6. Case Study - Data'!E11:E40,A26) -> 8
A27: Keyboard | B27: =SUMIFS('6. Case Study - Data'!H11:H40,'6. Case Study - Data'!E11:E40,A27) -> 2219.63 | C27: =SUMIFS('6. Case Study - Data'!F11:F40,'6. Case Study - Data'!E11:E40,A27) -> 37
A28: Mouse | B28: =SUMIFS('6. Case Study - Data'!H11:H40,'6. Case Study - Data'!E11:E40,A28) -> 1799.4 | C28: =SUMIFS('6. Case Study - Data'!F11:F40,'6. Case Study - Data'!E11:E40,A28) -> 60
A29: Headphones | B29: =SUMIFS('6. Case Study - Data'!H11:H40,'6. Case Study - Data'!E11:E40,A29) -> 2399.7 | C29: =SUMIFS('6. Case Study - Data'!F11:F40,'6. Case Study - Data'!E11:E40,A29) -> 30
A30: Desk | B30: =SUMIFS('6. Case Study - Data'!H11:H40,'6. Case Study - Data'!E11:E40,A30) -> 3149.91 | C30: =SUMIFS('6. Case Study - Data'!F11:F40,'6. Case Study - Data'!E11:E40,A30) -> 9
A31: Desk Chair | B31: =SUMIFS('6. Case Study - Data'!H11:H40,'6. Case Study - Data'!E11:E40,A31) -> 2849.81 | C31: =SUMIFS('6. Case Study - Data'!F11:F40,'6. Case Study - Data'!E11:E40,A31) -> 19
A32: Printer | B32: =SUMIFS('6. Case Study - Data'!H11:H40,'6. Case Study - Data'!E11:E40,A32) -> 1399.93 | C32: =SUMIFS('6. Case Study - Data'!F11:F40,'6. Case Study - Data'!E11:E40,A32) -> 7
A33: Filing Cabinet | B33: =SUMIFS('6. Case Study - Data'!H11:H40,'6. Case Study - Data'!E11:E40,A33) -> 1559.88 | C33: =SUMIFS('6. Case Study - Data'!F11:F40,'6. Case Study - Data'!E11:E40,A33) -> 12
A35: 📝 TASK 4: Monthly Sales Trend
A36: Analyze sales by month to identify trends
A38: Month | B38: Total Sales | C38: Orders | D38: Growth %
A39: January | B39: =SUMIFS('6. Case Study - Data'!H11:H40,'6. Case Study - Data'!B11:B40,">=2024-01-01",'6. Case Study - Data'!B11:B40,"<=2024-01-31") -> 6239.53 | C39: =COUNTIFS('6. Case Study - Data'!B11:B40,">=2024-01-01",'6. Case Study - Data'!B11:B40,"<=2024-01-31") -> 8 | D39: —
A40: February | B40: =SUMIFS('6. Case Study - Data'!H11:H40,'6. Case Study - Data'!B11:B40,">=2024-02-01",'6. Case Study - Data'!B11:B40,"<=2024-02-29") -> 12289.5 | C40: =COUNTIFS('6. Case Study - Data'!B11:B40,">=2024-02-01",'6. Case Study - Data'!B11:B40,"<=2024-02-29") -> 9 | D40: =(B40-B39)/B39 -> 0.96961951
A41: March | B41: =SUMIFS('6. Case Study - Data'!H11:H40,'6. Case Study - Data'!B11:B40,">=2024-03-01",'6. Case Study - Data'!B11:B40,"<=2024-03-31") -> 14348.92 | C41: =COUNTIFS('6. Case Study - Data'!B11:B40,">=2024-03-01",'6. Case Study - Data'!B11:B40,"<=2024-03-31") -> 13 | D41: =(B41-B40)/B40 -> 0.16757557
A43: 📝 TASK 5: Advanced Analysis with XLOOKUP & INDEX-MATCH
A45: Analysis Question | B45: Formula Used | C45: Result
A46: Highest single sale amount
A47: Product with highest total sales | B47: INDEX/MATCH with MAX | C47: =INDEX(A24:A33,MATCH(MAX(B24:B33),B24:B33,0)) -> Laptop
A48: Region with most orders | B48: INDEX/MATCH with MAX | C48: =INDEX(A7:A10,MATCH(MAX(C7:C10),C7:C10,0)) -> North
A49: Average Electronics sale | B49: AVERAGEIFS | C49: =AVERAGEIFS('6. Case Study - Data'!H11:H40,'6. Case Study - Data'!D11:D40,"Electronics") -> 1328.8011
A51: 💡 KEY INSIGHTS & RECOMMENDATIONS
...

Sheet 8. Practice Exercises
A1: ✏️ PRACTICE EXERCISES
A2: Test your skills with these practice exercises. Enter your answers in the yellow cells.
A4: 📘 EXERCISE 1: INTERMEDIATE FORMULAS
A6: Employee | B6: Department | C6: Salary | D6: Years | F6: Question | G6: Your Answer | H6: Expected
A7: Alice | B7: Sales | C7: 52000 | D7: 3 | F7: 1. Total salary of Sales dept: | H7: =SUMIF(B7:B14,"Sales",C7:C14) -> 165000
A8: Bob | B8: IT | C8: 68000 | D8: 5 | F8: 2. Count of IT employees: | H8: =COUNTIF(B7:B14,"IT") -> 3
A9: Carol | B9: Sales | C9: 55000 | D9: 4 | F9: 3. Average salary in HR: | H9: =AVERAGEIF(B7:B14,"HR",C7:C14) -> 49500
A10: David | B10: HR | C10: 48000 | D10: 2 | F10: 4. Sum salary where Years > 4: | H10: =SUMIFS(C7:C14,D7:D14,">4") -> 198000
A11: Emma | B11: IT | C11: 72000 | D11: 6 | F11: 5. Count employees with salary > 55000: | H11: =COUNTIF(C7:C14,">55000") -> 4
A12: Frank | B12: Sales | C12: 58000 | D12: 5 | F12: 6. Max salary in IT: | H12: =_xlfn.MAXIFS(C7:C14,B7:B14,"IT") -> 72000
A13: Grace | B13: HR | C13: 51000 | D13: 3 | F13: 7. Min years in Sales: | H13: =_xlfn.MINIFS(D7:D14,B7:B14,"Sales") -> 3
A14: Henry | B14: IT | C14: 65000 | D14: 4 | F14: 8. Find dept for Emma (INDEX-MATCH): | H14: =INDEX(B7:B14,MATCH("Emma",A7:A14,0)) -> IT
A16: 📗 EXERCISE 2: ADVANCED FORMULAS
A18: Product_ID | B18: Product | C18: Price | D18: Category | F18: Question | G18: Your Answer | H18: Expected
A19: P101 | B19: Widget A | C19: 25.99 | D19: Tools | F19: 1. XLOOKUP price for P103: | H19: =_xlfn.XLOOKUP("P103",A19:A23,C19:C23) -> 99.99
A20: P102 | B20: Widget B | C20: 34.5 | D20: Tools | F20: 2. XLOOKUP category for Widget B: | H20: =_xlfn.XLOOKUP("Widget B",B19:B23,D19:D23) -> Tools
A21: P103 | B21: Gadget X | C21: 99.99 | D21: Electronics | F21: 3. XLOOKUP P999 with error msg: | H21: =_xlfn.XLOOKUP("P999",A19:A23,B19:B23,"Not Found") -> Not Found
A22: P104 | B22: Gadget Y | C22: 149.99 | D22: Electronics | F22: 4. UNIQUE categories: | H22: {=_xlfn.UNIQUE(D19:D23)} -> Tools
A23: P105 | B23: Supply Z | C23: 12.5 | D23: Office | F23: 5. FILTER Electronics only: | H23: Electronics
F24: 6. LET: calc 15% tax on 100: | H24: Office
F25: 7. SEQUENCE 1 to 5: | H25: {=_xlfn._xlws.FILTER(A19:D23,D19:D23="Electronics")} -> P103 | I25: Gadget X | J25: 99.99 | K25: Electronics
H26: P104 | I26: Gadget Y | J26: 149.99 | K26: Electronics
H27: =_xlfn.LET(_xlpm.price,100,_xlpm.rate,0.15,_xlpm.price*_xlpm.rate) -> 15
H29: {=_xlfn.SEQUENCE(5,1,1,1)} -> 1
H30: 2
H31: 3
H32: 4
H33: 5
A35: 📙 EXERCISE 3: CASE STUDY CHALLENGE
A36: Using the Case Study data (Sheet 6), answer the following:
A38: Challenge Question | B38: Your Formula/Answer
A39: 1. What is the total revenue from Laptops?
A40: 2. How many orders were placed in the West region?
A41: 3. What is the average quantity per order for Electronics?
A42: 4. Which product generated the LEAST revenue?
A43: 5. What percentage of total orders came from the North region?
A44: 6. Find the highest priced item sold
A45: 7. How many unique products were sold?
A46: 8. What is the total revenue for orders with quantity >= 10?
A47: 9. Which month had the highest total sales?
...
